<?xml version="1.0"?>
<robot xmlns:xacro="http://www.ros.org/wiki/xacro">

    <xacro:include filename="inertial_macros.xacro" />

    <material name="white"> 
        <color rgba="1 1 1 1"/>
    </material>

    <material name="blue"> 
        <color rgba="0 0 0.1 1"/>
    </material>

    <material name="red"> 
        <color rgba="0.1 1 1 0.1"/>
    </material>

    <material name="teal"> 
        <color rgba="0 1 1 1"/>
    </material>

    <!-- BASE LINK -->
    <link name="base_link">
    </link>
    
    <!-- BODY LINK -->
    <joint name="body_joint" type="fixed">
        <parent link="base_link"/>
        <child link="body"/>
        <origin xyz="0.115 0 0.035"/>
    </joint>

    <link name="body">
        <visual>
            <origin xyz="0 0 0"/>
            <geometry>
                <box size="0.23 0.13 0.065"/>
            </geometry>
            <material name="white"/>
        </visual>
        <collision>
            <origin xyz="0 0 0"/>
            <geometry>
                <box size="0.23 0.13 0.065"/>
            </geometry>
        </collision>
        <xacro:inertial_box mass="0.5" x="0.23" y="0.13" z="0.065">
            <origin xyz="0 0 0" rpy="0 0 0"/>
        </xacro:inertial_box>
    </link>

    <!-- LEFT REAR WHEEL -->
    <joint name="left_rear_wheel_joint" type="continuous">
        <parent link="body"/>
        <child link="left_rear_wheel"/>
        <!-- Adjusted position relative to the body -->
        <origin xyz="-0.055 0.065 -0.005" rpy="-${pi/2} 0 0"/>
        <axis xyz="0 0 1"/>
    </joint>

    <link name="left_rear_wheel">
        <visual>
            <geometry>
                <cylinder radius="0.035" length="0.025"/>
            </geometry>
            <material name="blue"/>
        </visual>
        <collision>
            <geometry>
                <cylinder radius="0.035" length="0.025"/>
            </geometry>
        </collision>
        <xacro:inertial_cylinder mass="0.1" length="0.025" radius="0.035">
            <origin xyz="0 0 0" rpy="0 0 0"/>
        </xacro:inertial_cylinder>
    </link>

    <!-- LEFT FRONT WHEEL -->
    <joint name="left_front_wheel_joint" type="continuous">
        <parent link="body"/>
        <child link="left_front_wheel"/>
        <!-- Adjusted position relative to the body -->
        <origin xyz="0.055 0.065 -0.005" rpy="-${pi/2} 0 0"/>
        <axis xyz="0 0 1"/>
    </joint>

    <link name="left_front_wheel">
        <visual>
            <geometry>
                <cylinder radius="0.035" length="0.025"/>
            </geometry>
            <material name="blue"/>
        </visual>
        <collision>
            <geometry>
                <cylinder radius="0.035" length="0.025"/>
            </geometry>
        </collision>
        <xacro:inertial_cylinder mass="0.1" length="0.025" radius="0.035">
            <origin xyz="0 0 0" rpy="0 0 0"/>
        </xacro:inertial_cylinder>
    </link>

    <!-- RIGHT FRONT WHEEL -->
    <joint name="right_front_wheel_joint" type="continuous">
        <parent link="body"/>
        <child link="right_front_wheel"/>
        <!-- Adjusted position relative to the body -->
        <origin xyz="0.055 -0.065 -0.005" rpy="${pi/2} 0 0"/>
        <axis xyz="0 0 -1"/>
    </joint>

    <link name="right_front_wheel">
        <visual>
            <geometry>
                <cylinder radius="0.035" length="0.025"/>
            </geometry>
            <material name="blue"/>
        </visual>
        <collision>
            <geometry>
                <cylinder radius="0.035" length="0.025"/>
            </geometry>
            <material name="blue"/>
        </collision>
        <xacro:inertial_cylinder mass="0.1" length="0.025" radius="0.035">
            <origin xyz="0 0 0" rpy="0 0 0"/>
        </xacro:inertial_cylinder>
    </link>

    <!-- RIGHT REAR WHEEL -->
    <joint name="right_rear_wheel_joint" type="continuous">
        <parent link="body"/>
        <child link="right_rear_wheel"/>
        <!-- Adjusted position relative to the body -->
        <origin xyz="-0.055 -0.065 -0.005" rpy="${pi/2} 0 0"/>
        <axis xyz="0 0 -1"/>
    </joint>

    <link name="right_rear_wheel">
        <visual>
            <geometry>
                <cylinder radius="0.035" length="0.025"/>
            </geometry>
            <material name="blue"/>
        </visual>
        <collision>
            <geometry>
                <cylinder radius="0.035" length="0.025"/>
            </geometry>
        </collision>
        <xacro:inertial_cylinder mass="0.1" length="0.025" radius="0.035">
            <origin xyz="0 0 0" rpy="0 0 0"/>
        </xacro:inertial_cylinder>
    </link>

</robot>
